Workbook
Name Capex_Pct: Assumptions!$B$21
Name COGS_Pct: Assumptions!$B$14
Name Opex_Pct: Assumptions!$B$15
Name Rev_Growth_Base: Assumptions!$B$6
Name Rev_Growth_Bear: Assumptions!$B$8
Name Rev_Growth_Bull: Assumptions!$B$7
Name Tax_Rate: Assumptions!$B$19

Sheet Cover

Sheet Assumptions
A1: Assumptions
A3: Assumption | B3: Input | F3: Notes
A5: Revenue Assumptions | H5: Scenario | I5: ='Executive Dashboard'!E4
A6: Reference Revenue Growth (Not Scenario-Driven) | B6: 0.08 | F6: Normalized growth assumption
A7: Bull Case Growth Rate | B7: 0.11
A8: Bear Case Growth Rate | B8: 0.05
A9: Membership Growth Rate | B9: 0.06 | F9: Membership base expansion
A10: Avg Ticket Growth Rate | B10: 0.02 | F10: Pricing + mix
A11: Selected Growth Rate | B11: =IF($I$5="Base",$B$6,IF($I$5="Bull",$B$7,$B$8))
A13: Cost Assumptions
A14: COGS % of Revenue | B14: ='Drivers & Cost Structure'!E11
A15: Operating Expenses % of Revenue | B15: ='Drivers & Cost Structure'!E12
A16: EBITDA Margin | B16: =Sensitivity!$B$16
A18: Cash Flow Assumptions
A19: Effective Tax Rate | B19: 0.24
A20: Depreciation % of Revenue | B20: 0.016
A21: CapEx % of Revenue | B21: 0.018 | C21: 0.017 | D21: 0.02 | E21: =IF('Drivers & Cost Structure'!B1="Base", B21, IF('Drivers & Cost Structure'!B1="Bull", C21, IF('Drivers & Cost Structure'!B1="Bear", D21, "")))
A22: Working Capital % of Revenue | B22: 0.005
A24: Valuation Inputs (DCF)
A25: Risk-Free Rate | B25: 0.04
A26: Market Risk Premium | B26: 0.055
A27: Beta | B27: 0.8
A28: Cost of Debt | B28: 0.045
A29: Terminal Growth Rate | B29: 0.025

Sheet Historical Finances
A1: Line Item | B1: 2021 | C1: 2022 | D1: 2023 | E1: 2024 | F1: 2025
A3: Income Statement ($ in millions)
A5: Revenue | B5: 195929 | C5: 226954 | D5: 242290 | E5: 254453 | F5: 275235
A6: Cost of Goods Sold (COGS) | B6: 170684 | C6: 199382 | D6: 212586 | E6: 222358 | F6: 239886
A7: Gross Profit | B7: =B5-B6 | C7: =C5-C6 | D7: =D5-D6 | E7: =E5-E6 | F7: =F5-F6
A8: Operating Expenses | B8: 18537 | C8: 19779 | D8: 21590 | E8: 22810 | F8: 24966
A9: EBITDA | B9: =B7-B8 | C9: =C7-C8 | D9: =D7-D8 | E9: =E7-E8 | F9: =F7-F8
A10: Depreciation & Amortization
A11: EBIT (Operating Income) | B11: =B9-B10 | C11: =C9-C10 | D11: =D9-D10 | E11: =E9-E10 | F11: =F9-F10
A12: Interest Expense | B12: 171 | C12: 158 | D12: 160 | E12: 169 | F12: 154
A13: Pre-Tax Income | B13: =B11-B12 | C13: =C11-C12 | D13: =D11-D12 | E13: =E11-E12 | F13: =F11-F12
A14: Income Tax | B14: 1601 | C14: 1925 | D14: 2195 | E14: 2373 | F14: 2719
A15: Net Income | B15: 5007 | C15: 5844 | D15: 6292 | E15: 7367 | F15: 8099
A18: Balance Sheet ($ in millions)
A20: Assets
A21: Cash & Cash Equivalents | B21: 11258 | C21: 10203 | D21: 13700 | E21: 9906 | F21: 14161
A22: Short-Term Investments | B22: 917 | C22: 846 | D22: 1534 | E22: 1238 | F22: 1123
A23: Accounts Recievable | B23: 1803 | C23: 2241 | D23: 2285 | E23: 2721 | F23: 3203
A24: Inventory | B24: 14215 | C24: 17907 | D24: 16651 | E24: 18647 | F24: 18116
A25: Other Current Assets | B25: 1312 | C25: 1499 | D25: 1709 | E25: 1734 | F25: 1777
A26: Total Current Assets | B26: =SUM(B21:B25) | C26: =SUM(C21:C25) | D26: =SUM(D21:D25) | E26: =SUM(E21:E25) | F26: =SUM(F21:F25)
A28: Property, Plant & Equipment (PP&E) | B28: 23492 | C28: 24646 | D28: 26684 | E28: 29032 | F28: 31909
A29: Operating Lease Right of Use Assets | B29: 2890 | C29: 2774 | D29: 2713 | E29: 2617 | F29: 2725
A30: Other Long-Term Assets | B30: 3381 | C30: 4050 | D30: 3718 | E30: 3936 | F30: 4085
A31: Total Assets | B31: =B26+B28+B29+B30 | C31: =C26+C28+C29+C30 | D31: =D26+D28+D29+D30 | E31: =E26+E28+E29+E30 | F31: =F26+F28+F29+F30
A33: Liabilities
A34: Accounts Payable | B34: 16278 | C34: 17848 | D34: 17483 | E34: 19421 | F34: 19783
A35: Accrued Salaries & Benefits | B35: 4090 | C35: 4381 | D35: 4278 | E35: 4794 | F35: 5205
A36: Accrued Member Rewards | B36: 1671 | C36: 1911 | D36: 2150 | E36: 2434 | F36: 2677
A37: Deferred Membership Fees | B37: 2042 | C37: 2174 | D37: 2337 | E37: 2501 | F37: 2854
A38: Current Portion of Long Term Debt | B38: 799 | C38: 73 | D38: 1081 | E38: 0 | F38: 0
A39: Other Current Liabilities | B39: 4561 | C39: 5611 | D39: 6254 | E39: 6313 | F39: 6589
A40: Long-Term Debt | B40: 6692 | C40: 6484 | D40: 5377 | E40: 5794 | F40: 5713
A41: Operating Lease Liabilities | B41: 2642 | C41: 2482 | D41: 2426 | E41: 2375 | F41: 2460
A42: Other Liabilities | B42: 2415 | C42: 2555 | D42: 2550 | E42: 2576 | F42: 2654
A43: Total Liabilities | B43: =SUM(B34:B42) | C43: =SUM(C34:C42) | D43: =SUM(D34:D42) | E43: =SUM(E34:E42) | F43: =SUM(F34:F42)
A45: Equity
A46: Share Capital | B46: 4 | C46: 2 | D46: 2 | E46: 2 | F46: 2
A47: Additional Paid-In Capital | B47: 7031 | C47: 6884 | D47: 7340 | E47: 7830 | F47: 8282
A48: Retained Earnings | B48: 11666 | C48: 15585 | D48: 19521 | E48: 17619 | F48: 22650
...

Sheet Revenue Model
A1: Year | B1: Revenue | C1: $ Change | D1: % Growth | E1: Growth Index (base=100)
A2: 2021 | B2: ='Historical Finances'!B5 | E2: =100
A3: 2022 | B3: ='Historical Finances'!C5 | C3: =B3-B2 | D3: =(B3/B2)-1 | E3: =(B3/$B$2)*100
A4: 2023 | B4: ='Historical Finances'!D5 | C4: =B4-B3 | D4: =(B4/B3)-1 | E4: =(B4/$B$2)*100
A5: 2024 | B5: ='Historical Finances'!E5 | C5: =B5-B4 | D5: =(B5/B4)-1 | E5: =(B5/$B$2)*100
A6: 2025 | B6: ='Historical Finances'!F5 | C6: =B6-B5 | D6: =(B6/B5)-1 | E6: =(B6/$B$2)*100
A8: CAGR (overall growth per year) | C8: 0.088682481
B36: 2021A | C36: 2022A | D36: 2023A | E36: 2024A | F36: 2025A | G36: 2026E | H36: 2027E | I36: 2028E | J36: 2029E | K36: 2030E
A38: Revenue | B38: ='Historical Finances'!B5 | C38: ='Historical Finances'!C5 | D38: ='Historical Finances'!D5 | E38: ='Historical Finances'!E5 | F38: ='Historical Finances'!F5 | G38: =F38*(1+G40) | H38: =G38*(1+H40) | I38: =H38*(1+I40) | J38: =I38*(1+J40) | K38: =J38*(1+K40)
A40: Forecast Revenue Growth % | G40: ='Drivers & Cost Structure'!$E$7 | H40: ='Drivers & Cost Structure'!$E$7 | I40: ='Drivers & Cost Structure'!$E$7 | J40: ='Drivers & Cost Structure'!$E$7 | K40: ='Drivers & Cost Structure'!$E$7
A42: Revenue CAGR (2025A-2030E) | B42: 0.05575

Sheet Drivers & Cost Structure
A1: Scenario | B1: ='Executive Dashboard'!E4
A4: Revenue Assumptions
B5: Base | C5: Bull | D5: Bear | E5: Selected
A6: Store Growth % | B6: 0.025 | C6: 0.035 | D6: 0.015 | E6: =_xlfn.XLOOKUP($B$1,$B$5:$D$5,$B6:$D6)
A7: Comp Sales Growth % | B7: 0.03 | C7: 0.045 | D7: 0.015 | E7: =_xlfn.XLOOKUP($B$1,$B$5:$D$5,$B7:$D7)
A9: Cost Assumptions
B10: Base | C10: Bull | D10: Bear | E10: Selected
A11: COGS % of Revenue | B11: 0.885 | C11: 0.875 | D11: 0.89 | E11: =_xlfn.XLOOKUP($B$1,$B$10:$D$10,$B11:$D11)
A12: Operating Expenses % of Revenue | B12: 0.08 | C12: 0.075 | D12: 0.085 | E12: =_xlfn.XLOOKUP($B$1,$B$10:$D$10,$B12:$D12)

Sheet Cost Margin
B2: 2021A | C2: 2022A | D2: 2023A | E2: 2024A | F2: 2025A | G2: 2026E | H2: 2027E | I2: 2028E | J2: 2029E | K2: 2030E
A4: Revenue | B4: ='3-Statement Model'!B6 | C4: ='3-Statement Model'!C6 | D4: ='3-Statement Model'!D6 | E4: ='3-Statement Model'!E6 | F4: ='3-Statement Model'!F6 | G4: ='3-Statement Model'!G6 | H4: ='3-Statement Model'!H6 | I4: ='3-Statement Model'!I6 | ... K4: ='3-Statement Model'!K6
A5: COGS | B5: ='3-Statement Model'!B7 | C5: ='3-Statement Model'!C7 | D5: ='3-Statement Model'!D7 | E5: ='3-Statement Model'!E7 | F5: ='3-Statement Model'!F7 | G5: ='3-Statement Model'!G7 | H5: ='3-Statement Model'!H7 | I5: ='3-Statement Model'!I7 | ... K5: ='3-Statement Model'!K7
A6: Gross Profit | B6: =B4-B5 | C6: =C4-C5 | D6: =D4-D5 | E6: =E4-E5 | F6: =F4-F5 | G6: =G4-G5 | H6: =H4-H5 | I6: =I4-I5 | ... K6: =K4-K5
A7: Operating Expenses | B7: ='3-Statement Model'!B9 | C7: ='3-Statement Model'!C9 | D7: ='3-Statement Model'!D9 | E7: ='3-Statement Model'!E9 | F7: ='3-Statement Model'!F9 | G7: ='3-Statement Model'!G9 | H7: ='3-Statement Model'!H9 | I7: ='3-Statement Model'!I9 | ... K7: ='3-Statement Model'!K9
A8: EBITDA | B8: ='3-Statement Model'!B10 | C8: ='3-Statement Model'!C10 | D8: ='3-Statement Model'!D10 | E8: ='3-Statement Model'!E10 | F8: ='3-Statement Model'!F10 | G8: ='3-Statement Model'!G10 | H8: ='3-Statement Model'!H10 | I8: ='3-Statement Model'!I10 | ... K8: ='3-Statement Model'!K10
A9: Gross Margin % | B9: =B6/B4 | C9: =C6/C4 | D9: =D6/D4 | E9: =E6/E4 | F9: =F6/F4 | G9: =G6/G4 | H9: =H6/H4 | I9: =I6/I4 | ... K9: =K6/K4
A10: EBITDA % | B10: =B8/B4 | C10: =C8/C4 | D10: =D8/D4 | E10: =E8/E4 | F10: =F8/F4 | G10: =G8/G4 | H10: =H8/H4 | I10: =I8/I4 | ... K10: =K8/K4
A13: Margin Bridge (2025A-2030E)
A14: Gross Margin % change | B14: =K9-F9
A15: OpEx % change | B15: =(-$K$7/$K$4)-(-$F$7/$F$4)
A16: EBITDA Margin % change | B16: =$K$10-$F$10

Sheet 3-Statement Model
A2: Year | B2: 2021A | C2: 2022A | D2: 2023A | E2: 2024A | F2: 2025A | G2: 2026E | H2: 2027E | I2: 2028E | J2: 2029E | K2: 2030E
A4: Income Statement
A6: Revenue | B6: ='Revenue Model'!B38 | C6: ='Revenue Model'!C38 | D6: ='Revenue Model'!D38 | E6: ='Revenue Model'!E38 | F6: ='Revenue Model'!F38 | G6: ='Revenue Model'!G38 | H6: ='Revenue Model'!H38 | I6: ='Revenue Model'!I38 | ... K6: ='Revenue Model'!K38
A7: COGS | B7: ='Historical Finances'!B6 | C7: ='Historical Finances'!C6 | D7: ='Historical Finances'!D6 | E7: ='Historical Finances'!E6 | F7: ='Historical Finances'!F6 | G7: =G6 * Assumptions!$B$14 | H7: =H6 * Assumptions!$B$14 | I7: =I6 * Assumptions!$B$14 | J7: =J6 * Assumptions!$B$14 | K7: =K6 * Assumptions!$B$14
A8: Gross Profit | B8: =B6-B7 | C8: =C6-C7 | D8: =D6-D7 | E8: =E6-E7 | F8: =F6-F7 | G8: =G6-G7 | H8: =H6-H7 | I8: =I6-I7 | ... K8: =K6-K7
A9: Operating Expenses | B9: =B6*Opex_Pct | C9: ='Historical Finances'!C8 | D9: ='Historical Finances'!D8 | E9: ='Historical Finances'!E8 | F9: ='Historical Finances'!F8 | G9: =G6*Opex_Pct | H9: =H6*Opex_Pct | I9: =I6*Opex_Pct | J9: =J6*Opex_Pct | K9: =K6*Opex_Pct
A10: EBITDA | B10: =B8-B9 | C10: =C8-C9 | D10: =D8-D9 | E10: =E8-E9 | F10: =F8-F9 | G10: =G8-G9 | H10: =H8-H9 | I10: =I8-I9 | ... K10: =K8-K9
A11: Depreciation & Amortization | B11: =B6 * Assumptions!$B$20 | C11: =C6 * Assumptions!$B$20 | D11: =D6 * Assumptions!$B$20 | E11: =E6 * Assumptions!$B$20 | F11: =F6 * Assumptions!$B$20 | G11: =G6 * Assumptions!$B$20 | H11: =H6 * Assumptions!$B$20 | I11: =I6 * Assumptions!$B$20 | ... K11: =K6 * Assumptions!$B$20
A12: EBIT | B12: =B10-B11 | C12: =C10-C11 | D12: =D10-D11 | E12: =E10-E11 | F12: =F10-F11 | G12: =G10-G11 | H12: =H10-H11 | I12: =I10-I11 | ... K12: =K10-K11
A13: Taxes | B13: =IF(B12>0, B12 * Assumptions!$B$19, 0) | C13: =IF(C12>0, C12 * Assumptions!$B$19, 0) | D13: =IF(D12>0, D12 * Assumptions!$B$19, 0) | E13: =IF(E12>0, E12 * Assumptions!$B$19, 0) | F13: =IF(F12>0, F12 * Assumptions!$B$19, 0) | G13: =IF(G12>0, G12 * Assumptions!$B$19, 0) | H13: =IF(H12>0, H12 * Assumptions!$B$19, 0) | I13: =IF(I12>0, I12 * Assumptions!$B$19, 0) | ... K13: =IF(K12>0, K12 * Assumptions!$B$19, 0)
A14: Net Income | B14: =B12-B13 | C14: =C12-C13 | D14: =D12-D13 | E14: =E12-E13 | F14: =F12-F13 | G14: =G12-G13 | H14: =H12-H13 | I14: =I12-I13 | ... K14: =K12-K13
A17: Cash Flow Statement
A19: Net Income | B19: =B14 | C19: =C14 | D19: =D14 | E19: =E14 | F19: =F14 | G19: =G14 | H19: =H14 | I19: =I14 | ... K19: =K14
A20: Depreciation & Amortization | B20: =B11 | C20: =C11 | D20: =D11 | E20: =E11 | F20: =F11 | G20: =G11 | H20: =H11 | I20: =I11 | ... K20: =K11
A21: Change in Working Capital | B21: =0 | C21: =(C$6-B$6)*Assumptions!$B$22 | D21: =(D$6-C$6)*Assumptions!$B$22 | E21: =(E$6-D$6)*Assumptions!$B$22 | F21: =(F$6-E$6)*Assumptions!$B$22 | G21: =(G$6-F$6)*Assumptions!$B$22 | H21: =(H$6-G$6)*Assumptions!$B$22 | I21: =(I$6-H$6)*Assumptions!$B$22 | J21: =(J$6-I$6)*Assumptions!$B$22 | K21: =(K$6-J$6)*Assumptions!$B$22
A22: Cash Flow from Operations (CFO) | B22: =B19+B20-B21 | C22: =C19+C20-C21 | D22: =D19+D20-D21 | E22: =E19+E20-E21 | F22: =F19+F20-F21 | G22: =G19+G20-G21 | H22: =H19+H20-H21 | I22: =I19+I20-I21 | ... K22: =K19+K20-K21
A24: CapEx | B24: 0 | C24: 0 | D24: 0 | E24: 0 | F24: 0 | G24: =-G$6*Assumptions!$B$21 | H24: =-H$6*Assumptions!$B$21 | I24: =-I$6*Assumptions!$B$21 | J24: =-J$6*Assumptions!$B$21 | K24: =-K$6*Assumptions!$B$21
A25: Cash Flow from Investing (CFI) | B25: =B24 | C25: =C24 | D25: =D24 | E25: =E24 | F25: =F24 | G25: =G24 | H25: =H24 | I25: =I24 | ... K25: =K24
A27: Net Change in cash | B27: =B22+B25 | C27: =C22+C25 | D27: =D22+D25 | E27: =E22+E25 | F27: =F22+F25 | G27: =G22+G25 | H27: =H22+H25 | I27: =I22+I25 | ... K27: =K22+K25
A29: Beginning Cash | B29: ='Historical Finances'!B21 | C29: ='Historical Finances'!C21 | D29: ='Historical Finances'!D21 | E29: ='Historical Finances'!E21 | F29: ='Historical Finances'!F21 | G29: =F30 | H29: =G30 | I29: =H30 | J29: =I30 | K29: =J30
A30: Ending Cash | B30: ='Historical Finances'!B21 | C30: ='Historical Finances'!C21 | D30: ='Historical Finances'!D21 | E30: ='Historical Finances'!E21 | F30: ='Historical Finances'!F21 | G30: =G29+G27 | H30: =H29+H27 | I30: =I29+I27 | J30: =J29+J27 | K30: =K29+K27
A32: Free Cash Flow (FCFF) | G32: ='DCF Valuation'!B28 | H32: ='DCF Valuation'!C28 | I32: ='DCF Valuation'!D28 | J32: ='DCF Valuation'!E28 | K32: ='DCF Valuation'!F28
A34: Balance Sheet
A36: Cash | B36: =B30 | C36: =C30 | D36: =D30 | E36: =E30 | F36: =F30 | G36: =G30 | H36: =H30 | I36: =I30 | ... K36: =K30
A37: Net Working Capital | B37: =0 | C37: =0 | D37: =0 | E37: =0 | F37: =0 | G37: =G$6*Assumptions!$B$22 | H37: =H$6*Assumptions!$B$22 | I37: =I$6*Assumptions!$B$22 | J37: =J$6*Assumptions!$B$22 | K37: =K$6*Assumptions!$B$22
A38: PP&E (Net) | B38: ='Historical Finances'!B28 | C38: ='Historical Finances'!C28 | D38: ='Historical Finances'!D28 | E38: ='Historical Finances'!E28 | F38: ='Historical Finances'!F28 | G38: =F38 + G24 - G11 | H38: =G38 + H24 - H11 | I38: =H38 + I24 - I11 | J38: =I38 + J24 - J11 | K38: =J38 + K24 - K11
A39: Total Assets | B39: =B36+B37+B38 | C39: =C36+C37+C38 | D39: =D36+D37+D38 | E39: =E36+E37+E38 | F39: =F36+F37+F38 | G39: =G36+G37+G38 | H39: =H36+H37+H38 | I39: =I36+I37+I38 | ... K39: =K36+K37+K38
A41: Total Debt | B41: ='Historical Finances'!B38 + 'Historical Finances'!B40 | C41: ='Historical Finances'!C38 + 'Historical Finances'!C40 | D41: ='Historical Finances'!D38 + 'Historical Finances'!D40 | E41: ='Historical Finances'!E38 + 'Historical Finances'!E40 | F41: ='Historical Finances'!F38 + 'Historical Finances'!F40 | G41: =$F$41 | H41: =$F$41 | I41: =$F$41 | J41: =$F$41 | K41: =$F$41
A42: Equity (Plug) | B42: =B39-B41 | C42: =C39-C41 | D42: =D39-D41 | E42: =E39-E41 | F42: =F39-F41 | G42: =G39-G41 | H42: =H39-H41 | I42: =I39-I41 | ... K42: =K39-K41
A43: Total Liabilities & Equity | B43: =B41+B42 | C43: =C41+C42 | D43: =D41+D42 | E43: =E41+E42 | F43: =F41+F42 | G43: =G41+G42 | H43: =H41+H42 | I43: =I41+I42 | ... K43: =K41+K42
A44: Balance Check (Assets - L&E) | B44: =B39-B43 | C44: =C39-C43 | D44: =D39-D43 | E44: =E39-E43 | F44: =F39-F43 | G44: =G39-G43 | H44: =H39-H43 | I44: =I39-I43 | ... K44: =K39-K43

Sheet DCF Valuation
A1: DCF Valuation (FCFF)
A3: Risk-Free Rate | B3: =Assumptions!B25
A4: Market Risk Premium | B4: =Assumptions!B26
A5: Beta | B5: =Assumptions!B27
A6: Cost of Equity | B6: =B3+(B5*B4)
A7: Cost of Debt | B7: =Assumptions!B28
A8: Tax Rate | B8: =Assumptions!B19
A9: After-Tax Cost of Debt | B9: =B7*(1-B8)
A10: Debt Weight | B10: 0.2
A11: Equity Weight | B11: 0.8
A12: WACC | B12: =(B10*B9)+(B11*B6) | E12: WACC Input (for sensitivity) | H12: =Sensitivity!B3
A13: Terminal Growth (g) | B13: =Assumptions!B29 | E13: Terminal Growth (for sensitivity) | H13: =Sensitivity!B4
A16: ($ in millions) | B16: 2026E | C16: 2027E | D16: 2028E | E16: 2029E | F16: 2030E
A17: Revenue | B17: ='Revenue Model'!G38 | C17: ='Revenue Model'!H38 | D17: ='Revenue Model'!I38 | E17: ='Revenue Model'!J38 | F17: ='Revenue Model'!K38
A18: COGS | B18: =-B17*COGS_Pct | C18: =-C17*COGS_Pct | D18: =-D17*COGS_Pct | E18: =-E17*COGS_Pct | F18: =-F17*COGS_Pct
A19: Operating Expense | B19: =-B17*Opex_Pct | C19: =-C17*Opex_Pct | D19: =-D17*Opex_Pct | E19: =-E17*Opex_Pct | F19: =-F17*Opex_Pct
A20: EBITDA | B20: =B17+B18+B19 | C20: =C17+C18+C19 | D20: =D17+D18+D19 | E20: =E17+E18+E19 | F20: =F17+F18+F19
A21: D&A | B21: =B17*Assumptions!$B$20 | C21: =C17*Assumptions!$B$20 | D21: =D17*Assumptions!$B$20 | E21: =E17*Assumptions!$B$20 | F21: =F17*Assumptions!$B$20
A22: EBIT | B22: =B20-B21 | C22: =C20-C21 | D22: =D20-D21 | E22: =E20-E21 | F22: =F20-F21
A23: Taxes | B23: =IF(B22>0, B22*$B$8, 0) | C23: =IF(C22>0, C22*$B$8, 0) | D23: =IF(D22>0, D22*$B$8, 0) | E23: =IF(E22>0, E22*$B$8, 0) | F23: =IF(F22>0, F22*$B$8, 0)
A24: NOPAT | B24: =B22+B23 | C24: =C22+C23 | D24: =D22+D23 | E24: =E22+E23 | F24: =F22+F23
A25: CapEx | B25: =-B17*Capex_Pct | C25: =-C17*Capex_Pct | D25: =-D17*Capex_Pct | E25: =-E17*Capex_Pct | F25: =-F17*Capex_Pct
A26: NWC | B26: =B17*Assumptions!$B$22 | C26: =C17*Assumptions!$B$22 | D26: =D17*Assumptions!$B$22 | E26: =E17*Assumptions!$B$22 | F26: =F17*Assumptions!$B$22 | H26: 2025 NWC | I26: ='Revenue Model'!F38*Assumptions!B22
A27: Change in NWC | B27: =B26-$I$26 | C27: =C26-B26 | D27: =D26-C26 | E27: =E26-D26 | F27: =F26-E26
A28: FCFF | B28: =B24+B21+B25-B27 | C28: =C24+C21+C25-C27 | D28: =D24+D21+D25-D27 | E28: =E24+E21+E25-E27 | F28: =F24+F21+F25-F27
A30: Discount Factor | B30: =1/(1+$H$12)^1 | C30: =1/(1+$H$12)^2 | D30: =1/(1+$H$12)^3 | E30: =1/(1+$H$12)^4 | F30: =1/(1+$H$12)^5
A31: PV of FCFF | B31: =B28*B30 | C31: =C28*C30 | D31: =D28*D30 | E31: =E28*E30 | F31: =F28*F30
A33: Terminal Value (at 2030) | B33: =F28*(1+$H$13)/($H$12-$H$13)
A34: PV of Terminal Value | B34: =B33*F30
A36: Enterprise Value | B36: =SUM(B31:F31)+B34
A38: Total Debt (2025) | B38: ='Historical Finances'!F38+'Historical Finances'!F40
A39: Cash (2025) | B39: ='Historical Finances'!F21
A40: Short-Term Investments (2025) | B40: ='Historical Finances'!F22
A41: Net Debt (Debt-Cash-STI) | B41: =B38-B39-B40
A43: Equity Value | B43: =B36-B41

Sheet Sensitivity
A1: Sensitivity Analysis
A2: Base Case Valuation
A3: WACC (Sensitivity) | B3: ='DCF Valuation'!B12
A4: Terminal Growth (Sensitivity) | B4: ='DCF Valuation'!B13
A6: ='DCF Valuation'!B36 | B6: 0.06 | C6: 0.065 | D6: 0.07 | E6: 0.075 | F6: 0.08 | G6: 0.085 | H6: 0.09
A7: 0.015 | C7: 127926.54 | D7: 116229.17 | E7: 106482.51 | F7: 98236.36 | G7: 91169.159 | H7: 85045.099
A8: 0.02 | B8: 157258.68 | C8: 139729.31 | D8: 125706.75 | E8: 114234.57 | F8: 104675.17 | G8: 96587.106 | H8: 89655.086
A9: 0.025 | B9: 176587.86 | C9: 154482.78 | D9: 137290.45 | E9: 123537.05 | F9: 112284.67 | G9: 102908.04 | H9: 94974.303
A10: 0.03 | B10: 202360.11 | C10: 173451.52 | D10: 151770.08 | E10: 134906.74 | F10: 121416.07 | G10: 110378.24 | H10: 101180.06
A11: 0.035 | B11: 238441.26 | C11: 198743.18 | D11: 170386.75 | E11: 149118.86 | F11: 132576.67 | G11: 119342.48 | H11: 108514.13
A16: EBITDA Margin (Sensitivity) | B16: 0.02
A18: ='DCF Valuation'!B36 | B18: 0.06 | C18: 0.065 | D18: 0.07 | E18: 0.075 | F18: 0.08 | G18: 0.085 | H18: 0.09
A19: 0.02 | C19: 154482.78 | D19: 137290.45 | E19: 123537.05 | F19: 112284.67 | G19: 102908.04 | H19: 94974.303
A20: 0.03 | B20: 176587.86 | C20: 154482.78 | D20: 137290.45 | E20: 123537.05 | F20: 112284.67 | G20: 102908.04 | H20: 94974.303
A21: 0.04 | B21: 176587.86 | C21: 154482.78 | D21: 137290.45 | E21: 123537.05 | F21: 112284.67 | G21: 102908.04 | H21: 94974.303
A22: 0.05 | B22: 176587.86 | C22: 154482.78 | D22: 137290.45 | E22: 123537.05 | F22: 112284.67 | G22: 102908.04 | H22: 94974.303
A23: 0.06 | B23: 176587.86 | C23: 154482.78 | D23: 137290.45 | E23: 123537.05 | F23: 112284.67 | G23: 102908.04 | H23: 94974.303

Sheet Executive Dashboard
A2: Valuation Summary | G2: Key Assumptions
A4: Enterprise Value | B4: ='DCF Valuation'!B36 | D4: Scenario | E4: Bull | G4: Scenario | H4: =E4
A5: Equity Value | B5: ='DCF Valuation'!B43 | G5: WACC | H5: ='DCF Valuation'!B12
A6: Implied Upside/(Downside) | G6: Terminal Growth | H6: ='DCF Valuation'!B13
G7: Revenue CAGR (2025-2030) | H7: ='Revenue Model'!B42
G8: EBITDA Margin (Steady-State) | H8: ='Cost Margin'!K10
A45: 5780.246 | B45: 0.06 | C45: 0.065 | D45: 0.07 | E45: 0.075 | F45: 0.08 | G45: 0.085 | H45: 0.09
A46: 0.015 | B46: 5940.007 | C46: 5342.8387 | D46: 4854.2996 | E46: 4447.2312 | F46: 4102.8315 | G46: 3807.6706 | H46: 3551.8999
A47: 0.02 | B47: 6567.8926 | C47: 5835.7804 | D47: 5250.1296 | E47: 4770.9953 | F47: 4371.7477 | G47: 4033.9506 | H47: 3744.4355
A48: 0.025 | B48: 7375.1741 | C48: 6451.9575 | D48: 5733.9218 | E48: 5159.5122 | F48: 4689.5577 | G48: 4297.9439 | H48: 3966.5921
A49: 0.03 | B49: 8451.5494 | C49: 7244.1852 | D49: 6338.6621 | E49: 5634.3663 | F49: 5070.9296 | G49: 4609.936 | H49: 4225.7747
A50: 0.035 | B50: 9958.4749 | C50: 8300.4888 | D50: 7116.1852 | E50: 6227.9338 | F50: 5537.0509 | G50: 4984.3266 | H50: 4532.0814

Sheet Tableau Export
A1: Year | B1: Scenario | C1: Revenue | D1: EBITDA | E1: FCFF | F1: Enterprise Value (Scenario-Level)
A2: 2026E | B2: ='Executive Dashboard'!$E$4 | C2: ='Revenue Model'!G38 | D2: ='3-Statement Model'!G10 | E2: ='DCF Valuation'!B28 | F2: ='DCF Valuation'!$B$36
A3: 2027E | B3: ='Executive Dashboard'!$E$4 | C3: ='Revenue Model'!H38 | D3: ='3-Statement Model'!H10 | E3: ='DCF Valuation'!C28 | F3: ='DCF Valuation'!$B$36
A4: 2028E | B4: ='Executive Dashboard'!$E$4 | C4: ='Revenue Model'!I38 | D4: ='3-Statement Model'!I10 | E4: ='DCF Valuation'!D28 | F4: ='DCF Valuation'!$B$36
A5: 2029E | B5: ='Executive Dashboard'!$E$4 | C5: ='Revenue Model'!J38 | D5: ='3-Statement Model'!J10 | E5: ='DCF Valuation'!E28 | F5: ='DCF Valuation'!$B$36
A6: 2030E | B6: ='Executive Dashboard'!$E$4 | C6: ='Revenue Model'!K38 | D6: ='3-Statement Model'!K10 | E6: ='DCF Valuation'!F28 | F6: ='DCF Valuation'!$B$36
A11: 2026E | B11: Base (Frozen) | C11: 283492.05 | D11: 5669.841 | E11: 253.54648 | F11: 5780.246
A12: 2027E | B12: Base (Frozen) | C12: 291996.81 | D12: 5839.9362 | E12: 261.15288 | F12: 5780.246
A13: 2028E | B13: Base (Frozen) | C13: 300756.72 | D13: 6015.1343 | E13: 268.98746 | F13: 5780.246
A14: 2029E | B14: Base (Frozen) | C14: 309779.42 | D14: 6195.5883 | E14: 277.05709 | F14: 5780.246
A15: 2030E | B15: Base (Frozen) | C15: 319072.8 | D15: 6381.456 | E15: 285.3688 | F15: 5780.246
A21: 2026E | B21: Bull (Frozen) | C21: 287620.58 | D21: 5752.4115 | E21: 237.19752 | F21: 5697.4519
A22: 2027E | B22: Bull (Frozen) | C22: 300563.5 | D22: 6011.27 | E22: 247.87141 | F22: 5697.4519
A23: 2028E | B23: Bull (Frozen) | C23: 314088.86 | D23: 6281.7772 | E23: 259.02563 | F23: 5697.4519
A24: 2029E | B24: Bull (Frozen) | C24: 328222.86 | D24: 6564.4571 | E24: 270.68178 | F24: 5697.4519
A25: 2030E | B25: Bull (Frozen) | C25: 342992.89 | D25: 6859.8577 | E25: 282.86246 | F25: 5697.4519
A31: 2026E | B31: Bear (Frozen) | C31: 279363.53 | D31: 5587.2705 | E31: 269.89544 | F31: 5836.6903
A32: 2027E | B32: Bear (Frozen) | C32: 283553.98 | D32: 5671.0796 | E32: 273.94387 | F32: 5836.6903
... A35: 2030E | B35: Bear (Frozen) | C35: 296506.26 | D35: 5930.1253 | E35: 286.45718 | F35: 5836.6903
